Workbook

Sheet 04_09
A1: Tableau des performances hebdomadaires au 04-09-2026
A2: CODE ISIN | B2: Code Maroclear | C2: OPCVM | D2: Société de Gestion | E2: Nature juridique | F2: Classification | G2: Sensibilité | H2: Indice Bentchmark | I2: Périodicité VL | J2: Souscripteurs | K2: Affectation des résultats | L2: Commission de souscription | M2: Commission de rachat | N2: Frais de gestion | O2: Dépositaire | P2: Réseau placeur | Q2: AN | R2: VL | S2: YTD | T2: 1 jour | U2: 1 semaine | V2: 1 mois | W2: 3 mois | X2: 6 mois | Y2: 1 an | Z2: 2 ans | AA2: 3 ans | AB2: 5 ans
A3: MA0000030058 | B3: 3005 | C3: BMCI COSMOS | D3: CIH CAPITAL MANAGEMENT | E3: SICAV | F3: ACTIONS | G3: - | H3: MASI | I3: HEBDOMADAIRE | J3: FGP | K3: CAPITALISANT | L3: 0.02 | M3: 0.0075 | N3: 0.02 | O3: BMCI | P3: CIH CAPITAL MANAGEMENT | Q3: 29912657 | R3: 446 | S3: 0.022818 | T3: - | U3: -0.004886 | V3: -0.000583 | W3: 0.040549 | X3: 0.114109 | Y3: -0.079786 | Z3: 0.361458 | AA3: 0.603451 | AB3: 0.518298
A4: MA0000030066 | B4: 3006 | C4: BMCI EPARGNE OBLIGATIONS | D4: CIH CAPITAL MANAGEMENT | E4: SICAV | F4: OMLT | G4: [3 7[ | H4: MBI MLT | I4: HEBDOMADAIRE | J4: FGP | K4: CAPITALISANT | L4: 0.005 | M4: 0.0025 | N4: 0.0093 | O4: BMCI | P4: CIH CAPITAL MANAGEMENT | Q4: 1.1605659e+08 | R4: 274.32 | S4: -0.008566 | T4: - | U4: -0.001274 | V4: 0.00168 | W4: 0.003218 | X4: 0.000292 | Y4: -0.012029 | Z4: 0.059151 | AA4: 0.158201 | AB4: 0.091083
A5: MA0000030132 | B5: 3013 | C5: BMCI TRESORERIE | D5: CIH CAPITAL MANAGEMENT | E5: SICAV | F5: MONÉTAIRE | G5: [0 0,5[ | H5: TMJ(jj) | I5: QUOTIDIENNE | J5: FGP | K5: CAPITALISANT | L5: 0.0125 | M5: 0.005 | N5: 0.0195 | O5: BMCI | P5: CIH CAPITAL MANAGEMENT | Q5: 1.6391313e+08 | R5: 123521.58 | S5: 0.010523 | T5: - | U5: 0.000191 | V5: 0.00109 | W5: 0.003674 | X5: 0.007571 | Y5: 0.014885 | Z5: 0.032864 | AA5: 0.056679 | AB5: 0.083922
A6: MA0000030215 | B6: 3021 | C6: CDG IZDIHAR | D6: CDG CAPITAL GESTION | E6: SICAV | F6: DIVERSIFIÉ | G6: - | H6: 77% MBI GLOBAL + 23% CFG 25 FLOTTANT | I6: HEBDOMADAIRE | J6: FGP | K6: CAPITALISANT | L6: 0.003 | M6: 0.0025 | N6: 0.02 | O6: CDG CAPITAL | P6: CDG CAPITAL GESTION | Q6: 1.3031416e+09 | R6: 4122.96 | S6: -0.039826 | T6: - | U6: -0.006113 | V6: -0.007599 | W6: 0.010411 | X6: 0.010312 | Y6: -0.101456 | Z6: 0.119001 | AA6: 0.26625 | AB6: 0.176862
A7: MA0000030280 | B7: 3028 | C7: CDG TAWFIR | D7: CDG CAPITAL GESTION | E7: SICAV | F7: OMLT | G7: [3 7[ | H7: MBI GLOBAL | I7: QUOTIDIENNE | J7: FGP | K7: CAPITALISANT | L7: 0.005 | M7: 0 | N7: 0.02 | O7: CDG CAPITAL | P7: CDG CAPITAL GESTION | Q7: 1.7829964e+09 | R7: 3473.73 | S7: -0.001116 | T7: - | U7: -0.001839 | V7: 0.002016 | W7: 0.006455 | X7: 0.007705 | Y7: -0.008234 | Z7: 0.072695 | AA7: 0.16799 | AB7: 0.103816
A8: MA0000030298 | B8: 3029 | C8: SICAV OBLIGATIONS PÉRENNITÉ | D8: CDG CAPITAL GESTION | E8: SICAV | F8: OMLT | G8: [1,1 16[ | H8: MBI MT | I8: QUOTIDIENNE | J8: FNPP | K8: CAPITALISANT | L8: 0.03 | M8: 0.015 | N8: 0.02 | O8: CDG CAPITAL | P8: CDG CAPITAL GESTION | Q8: 6.2754921e+09 | R8: 3297.68 | S8: -0.005453 | T8: - | U8: -0.001729 | V8: 0.00126 | W8: 0.005029 | X8: 0.008388 | Y8: -0.004913 | Z8: 0.048107 | AA8: 0.103918 | AB8: 0.118062
A9: MA0000030306 | B9: 3030 | C9: CDG TRESORERIE | D9: CDG CAPITAL GESTION | E9: SICAV | F9: MONÉTAIRE | G9: [0 0,5[ | H9: 50% MBI CT + 50% TMP | I9: QUOTIDIENNE | J9: FGP | K9: CAPITALISANT | L9: 0 | M9: 0 | N9: 0.02 | O9: CDG CAPITAL | P9: CDG CAPITAL GESTION | Q9: 4.5357895e+09 | R9: 2280.17 | S9: 0.018825 | T9: - | U9: 0.00043 | V9: 0.002066 | W9: 0.006929 | X9: 0.014166 | Y9: 0.026535 | Z9: 0.056671 | AA9: 0.09378 | AB9: 0.138508
A10: MA0000030363 | B10: 3036 | C10: BMCI EPARGNE CROISSANCE | D10: CIH CAPITAL MANAGEMENT | E10: SICAV | F10: DIVERSIFIÉ | G10: - | H10: 60% MASI + 40% MBI MT | I10: HEBDOMADAIRE | J10: FGP | K10: CAPITALISANT | L10: 0.0125 | M10: 0.005 | N10: 0.0195 | O10: BMCI | P10: CIH CAPITAL MANAGEMENT | Q10: 2.6853808e+08 | R10: 165.02 | S10: -0.018556 | T10: - | U10: -0.002539 | V10: 0.000667 | W10: 0.014821 | X10: 0.017951 | Y10: -0.048712 | Z10: 0.128419 | AA10: 0.268799 | AB10: 0.270949
A11: MA0000030371 | B11: 3037 | C11: CIMR TRESO PLUS | D11: SAHAM CAPITAL GESTION | E11: SICAV | F11: OCT | G11: ]0,5 1,1] | H11: MBI CT | I11: QUOTIDIENNE | J11: FNPP | K11: CAPITALISANT | L11: 0 | M11: 0 | N11: 0.02 | O11: SAHAM BANK | P11: SAHAM BANK | Q11: 1.3709135e+08 | R11: 403209.84 | S11: 0.01626 | T11: - | U11: 1.4e-05 | V11: 0.001604 | W11: 0.005912 | X11: 0.012494 | Y11: 0.021415 | Z11: 0.05054 | AA11: 0.08842 | AB11: 0.131864
A12: MA0000030397 | B12: 3039 | C12: CDG BARID | D12: CDG CAPITAL GESTION | E12: SICAV | F12: OMLT | G12: [3 7[ | H12: - | I12: HEBDOMADAIRE | J12: FNPP | K12: CAPITALISANT | L12: 0.005 | M12: 0 | N12: 0.02 | O12: CDG | P12: CDG CAPITAL GESTION | Q12: 3.3974661e+09 | R12: 3728.81 | S12: -0.00703 | T12: - | U12: -0.002015 | V12: 0.001528 | W12: 0.006291 | X12: 0.006008 | Y12: -0.018311 | Z12: 0.070055 | AA12: 0.181589 | AB12: 0.07522
A13: MA0000030405 | B13: 3040 | C13: SICAV MAROC CROISSANCE | D13: MAROGEST | E13: SICAV | F13: DIVERSIFIÉ | G13: - | H13: - | I13: HEBDOMADAIRE | J13: FGP | K13: CAPITALISANT | L13: 0.02 | M13: 0.005 | N13: 0.02 | O13: CIH BANK | P13: MAROGEST | Q13: 3.0421617e+08 | R13: 5184.32 | S13: -0.044115 | T13: - | U13: -0.005624 | V13: -0.007506 | W13: 0.021513 | X13: 0.020266 | Y13: -0.106697 | Z13: 0.140391 | AA13: 0.348819 | AB13: 0.331898
A14: MA0000030413 | B14: 3041 | C14: BMCI CASH | D14: CIH CAPITAL MANAGEMENT | E14: SICAV | F14: OCT | G14: [0,6 1,1[ | H14: MBI CT | I14: QUOTIDIENNE | J14: FGP | K14: CAPITALISANT | L14: 0 | M14: 0 | N14: 0.0067 | O14: BMCI | P14: CIH CAPITAL MANAGEMENT | Q14: 31345674 | R14: 196.49 | S14: 0.021152 | T14: - | U14: -0.000204 | V14: 0.001325 | W14: 0.007744 | X14: 0.018505 | Y14: 0.030308 | Z14: 0.062108 | AA14: 0.093312 | AB14: 0.115596
... A57: MA0000035453 | B57: 3545 | C57: SCR INTEGRALE | D57: CDG CAPITAL GESTION | E57: FCP | F57: ACTIONS | G57: - | H57: CFG 25 FLOTTANT | I57: HEBDOMADAIRE | J57: FNPP | K57: DISTRIBUANT | L57: 0.03 | M57: 0.015 | N57: 0.02 | O57: CDG CAPITAL | P57: CDG CAPITAL GESTION | Q57: 2.2687803e+08 | R57: 6590.11 | S57: -0.052809 | T57: - | U57: -0.00706 | V57: -0.010015 | W57: 0.034424 | X57: 0.072964 | Y57: -0.144061 | Z57: 0.257316 | AA57: 0.504322 | AB57: 0.407589
A58: MA0000035461 | B58: 3546 | C58: SCR OBLIGATIONS | D58: CDG CAPITAL GESTION | E58: FCP | F58: OMLT | G58: ]1,1 9] | H58: MBI GLOBAL | I58: HEBDOMADAIRE | J58: FNPP | K58: CAPITALISANT | L58: 0 | M58: 0 | N58: - | O58: CDG CAPITAL | P58: CDG CAPITAL GESTION | Q58: 2.4192688e+09 | R58: 2729.51 | S58: -0.002011 | T58: - | U58: -0.001697 | V58: 0.001596 | W58: 0.006022 | X58: 0.00625 | Y58: -0.008113 | Z58: 0.071213 | AA58: 0.180613 | AB58: 0.0799
A59: MA0000035487 | B59: 3548 | C59: CDG ACTIONS | D59: CDG CAPITAL GESTION | E59: FCP | F59: ACTIONS | G59: - | H59: CFG 25 FLOTTANT | I59: HEBDOMADAIRE | J59: FNPP | K59: CAPITALISANT | L59: 0.03 | M59: 0.015 | N59: 0.02 | O59: CDG CAPITAL | P59: CDG CAPITAL GESTION | Q59: 1.7631212e+09 | R59: 7646.06 | S59: -0.030572 | T59: - | U59: -0.006923 | V59: -0.005075 | W59: 0.043029 | X59: 0.092167 | Y59: -0.129349 | Z59: 0.233619 | AA59: 0.41789 | AB59: 0.345518
A60: MA0000035495 | B60: 3549 | C60: AL IKRAM | D60: CIH CAPITAL MANAGEMENT | E60: FCP | F60: DIVERSIFIÉ | G60: - | H60: 60% MASI + 40% MBI MT | I60: HEBDOMADAIRE | J60: FNPP | K60: CAPITALISANT | L60: 0.03 | M60: 0.015 | N60: 0.0075 | O60: BMCI | P60: CIH CAPITAL MANAGEMENT | Q60: 34904035 | R60: 36741.09 | S60: -0.003606 | T60: - | U60: -0.003014 | V60: -0.003003 | W60: 0.012287 | X60: 0.028333 | Y60: -0.027695 | Z60: 0.118192 | AA60: 0.230117 | AB60: 0.250894
A61: MA0000035503 | B61: 3550 | C61: CASACTIONS | D61: CIH CAPITAL MANAGEMENT | E61: FCP | F61: DIVERSIFIÉ | G61: - | H61: 80% MBI GLOBAL + 20% MASI | I61: HEBDOMADAIRE | J61: FNPP | K61: DISTRIBUANT | L61: 0.03 | M61: 0.015 | N61: 0.02 | O61: BMCI | P61: CIH CAPITAL MANAGEMENT | Q61: 2469193.4 | R61: 176370.96 | S61: -0.000666 | T61: - | U61: -0.00132 | V61: 9.1e-05 | W61: 0.002939 | X61: 0.003895 | Y61: -0.002508 | Z61: 0.008793 | AA61: 0.030742 | AB61: 0.030856
A62: MA0000035511 | B62: 3551 | C62: AVENIR ACTIONS | D62: CIH CAPITAL MANAGEMENT | E62: FCP | F62: DIVERSIFIÉ | G62: - | H62: 80% MBI GLOBAL + 20% MASI | I62: HEBDOMADAIRE | J62: FNPP | K62: DISTRIBUANT | L62: 0.03 | M62: 0.015 | N62: 0.02 | O62: BMCI | P62: CIH CAPITAL MANAGEMENT | Q62: 2.2489874e+08 | R62: 248781.79 | S62: -0.004295 | T62: - | U62: -0.002795 | V62: -0.001347 | W62: 0.017301 | X62: 0.038092 | Y62: -0.04996 | Z62: 0.123381 | AA62: 0.25473 | AB62: 0.24155
A63: MA0000035529 | B63: 3552 | C63: AXA HORIZON | D63: CIH CAPITAL MANAGEMENT | E63: FCP | F63: DIVERSIFIÉ | G63: - | H63: CFG 25 FLOTTANT | I63: HEBDOMADAIRE | J63: FNPP | K63: MIXTE | L63: 0.03 | M63: 0.015 | N63: 0 | O63: BMCI | P63: CIH CAPITAL MANAGEMENT | Q63: 8.2026232e+08 | R63: 180555.21 | S63: 0.005176 | T63: - | U63: -0.003479 | V63: 0.001572 | W63: 0.016786 | X63: 0.033842 | Y63: -0.028386 | Z63: 0.180174 | AA63: 0.331473 | AB63: 0.287046
A64: MA0000035537 | B64: 3553 | C64: CIMR THARWA | D64: CIH CAPITAL MANAGEMENT | E64: FCP | F64: ACTIONS | G64: - | H64: MASI RN | I64: HEBDOMADAIRE | J64: FNPP | K64: CAPITALISANT | L64: 0 | M64: 0 | N64: 0.02 | O64: BMCI | P64: CIH CAPITAL MANAGEMENT | Q64: 1.1474379e+09 | R64: 516398.69 | S64: 0.023638 | T64: - | U64: -0.005243 | V64: -0.000221 | W64: 0.039627 | X64: 0.119705 | Y64: -0.06798 | Z64: 0.380424 | AA64: 0.652045 | AB64: 0.6405
A65: MA0000035545 | B65: 3554 | C65: BMCI INVEST | D65: CIH CAPITAL MANAGEMENT | E65: FCP | F65: DIVERSIFIÉ | G65: - | H65: 60% MASI + 40% MBI MT | I65: HEBDOMADAIRE | J65: FNPP | K65: CAPITALISANT | L65: 0.03 | M65: 0.015 | N65: 0.006 | O65: BMCI | P65: CIH CAPITAL MANAGEMENT | Q65: 836725.61 | R65: 239.06 | S65: 0.001592 | T65: - | U65: -0.000836 | V65: -0.003335 | W65: -0.006566 | X65: 0.005256 | Y65: -0.015323 | Z65: 0.039889 | AA65: 0.066899 | AB65: 0.056479
A66: MA0000035552 | B66: 3555 | C66: AXA AVENIR | D66: CDG CAPITAL GESTION | E66: FCP | F66: DIVERSIFIÉ | G66: - | H66: 80% MBI GLOBAL + 25% MASI RN | I66: HEBDOMADAIRE | J66: FNPP | K66: MIXTE | L66: 0.03 | M66: 0.015 | N66: 0.02 | O66: CDG CAPITAL | P66: CDG CAPITAL GESTION | Q66: 7.7920621e+08 | R66: 3643.09 | S66: -0.020483 | T66: - | U66: -0.003059 | V66: -0.000373 | W66: 0.016842 | X66: 0.025065 | Y66: -0.06431 | Z66: 0.134575 | AA66: 0.25304 | AB66: 0.194221
A67: MA0000035594 | B67: 3559 | C67: HORIZON BALANCED FUND | D67: SAHAM CAPITAL GESTION | E67: FCP | F67: DIVERSIFIÉ | G67: - | H67: 50% MBI GLOBAL + 50% MASI | I67: QUOTIDIENNE | J67: FGP | K67: DISTRIBUANT | L67: 0.02 | M67: 0.015 | N67: 0.02 | O67: SAHAM BANK | P67: SAHAM BANK | Q67: 1283355 | R67: 106946.25 | S67: -0.009335 | T67: - | U67: -0.003825 | V67: -0.001666 | W67: -0.016707 | X67: 0.027542 | Y67: -0.059033 | Z67: 0.170037 | AA67: 0.356049 | AB67: 0.367711
A68: MA0000035651 | B68: 3565 | C68: ATLAS PREMIUM | D68: ATLAS CAPITAL MANAGEMENT | E68: FCP | F68: ACTIONS | G68: - | H68: MASI | I68: HEBDOMADAIRE | J68: FGP | K68: CAPITALISANT | L68: 0.03 | M68: 0.015 | N68: 0.015 | O68: CIH BANK | P68: ATLAS CAPITAL MANAGEMENT | Q68: 1037503.6 | R68: 756.74 | S68: 0.035949 | T68: - | U68: -0.005493 | V68: -0.001069 | W68: 0.042873 | X68: 0.132912 | Y68: -0.062687 | Z68: 0.416586 | AA68: 0.695814 | AB68: 0.627363
A69: MA0000035677 | B69: 3567 | C69: CDG HORIZONS | D69: CDG CAPITAL GESTION | E69: FCP | F69: OMLT | G69: ]1,1 5,1] | H69: 50% MBI MLT + 50% MBI MT | I69: QUOTIDIENNE | J69: FGP | K69: CAPITALISANT | L69: 0.03 | M69: 0.015 | N69: 0.02 | O69: CDG CAPITAL | P69: CDG CAPITAL GESTION | Q69: 2.3080208e+08 | R69: 2258.44 | S69: 0.00767 | T69: - | U69: -0.000571 | V69: 0.002873 | W69: 0.006695 | X69: 0.010949 | Y69: 0.012976 | Z69: 0.080175 | AA69: 0.142565 | AB69: 0.131069
A70: MA0000035685 | B70: 3568 | C70: AVENIR OBLIGATION | D70: CFG GESTION | E70: FCP | F70: OMLT | G70: [4 8[ | H70: CFG BONDS MT | I70: HEBDOMADAIRE | J70: FNPP | K70: MIXTE | L70: 0 | M70: 0 | N70: 0.01 | O70: ATTIJARIWAFA BANK | P70: CFG GESTION | Q70: 1.4018328e+09 | R70: 26103.92 | S70: -0.00296 | T70: - | U70: -0.000841 | V70: 0.001712 | W70: 0.002787 | X70: 0.000875 | Y70: -0.012978 | Z70: 0.068703 | AA70: 0.178266 | AB70: 0.087156
... A118: MA0000036329 | B118: 3632 | C118: FCP CAPITAL TERME | D118: BMCE CAPITAL GESTION | E118: FCP | F118: DIVERSIFIÉ | G118: - | H118: 80% MBI GLOBAL + 20% MASI | I118: QUOTIDIENNE | J118: FGP | K118: CAPITALISANT | L118: 0.02 | M118: 0.02 | N118: 0.02 | O118: BANK OF AFRICA | P118: BMCE CAPITAL GESTION | Q118: 81016220 | R118: 248.04 | S118: 0.021666 | T118: - | U118: -0.001811 | V118: 0.000161 | W118: 0.028401 | X118: 0.047334 | Y118: -0.007205 | Z118: 0.162651 | AA118: 0.298775 | AB118: 0.251337
A119: MA0000036345 | B119: 3634 | C119: CFG INSTIBONDS | D119: CFG GESTION | E119: FCP | F119: OMLT | G119: ]1,5 5,5] | H119: MBI GLOBAL | I119: QUOTIDIENNE | J119: FGP | K119: CAPITALISANT | L119: 0.03 | M119: 0.015 | N119: 0.02 | O119: CFG BANK | P119: CFG GESTION; CFG BANK | Q119: 5.5279949e+08 | R119: 34.17 | S119: 0.002347 | T119: - | U119: -0.000585 | V119: 0.002641 | W119: 0.005888 | X119: 0.002935 | Y119: -0.780045 | Z119: -0.767741 | AA119: -0.755089 | AB119: -
A120: MA0000036352 | B120: 3635 | C120: FCP CAM TRESO PLUS | D120: MAROGEST | E120: FCP | F120: OCT | G120: ]0,5 1,1] | H120: 85% MBI CT + 15 % MBI MT | I120: QUOTIDIENNE | J120: FGP | K120: CAPITALISANT | L120: 0.03 | M120: 0.015 | N120: 0.02 | O120: CIH BANK | P120: CIH | Q120: 8.7249453e+08 | R120: 174.79 | S120: 0.018887 | T120: - | U120: -0.000172 | V120: 0.001834 | W120: 0.006565 | X120: 0.014275 | Y120: 0.025703 | Z120: 0.061521 | AA120: 0.104448 | AB120: 0.151525
A121: MA0000036378 | B121: 3637 | C121: AVENIR CROISSANCE | D121: CFG GESTION | E121: FCP | F121: ACTIONS | G121: - | H121: CFG 25 FLOTTANT | I121: HEBDOMADAIRE | J121: FNPP | K121: MIXTE | L121: 0.03 | M121: 0.015 | N121: 0.02 | O121: ATTIJARIWAFA BANK | P121: CFG GESTION | Q121: 1297620 | R121: 36045 | S121: -0.038979 | T121: - | U121: -0.003356 | V121: -0.009605 | W121: 0.024839 | X121: 0.051134 | Y121: -0.121713 | Z121: 0.202729 | AA121: 0.458283 | AB121: 0.434454
A122: MA0000036394 | B122: 3639 | C122: FCP CAPITAL TAALIM | D122: BMCE CAPITAL GESTION | E122: FCP | F122: OMLT | G122: [4 8[ | H122: 95% MBI MLT + 5% MASI | I122: HEBDOMADAIRE | J122: FNPP | K122: CAPITALISANT | L122: 0.03 | M122: 0.015 | N122: 0.02 | O122: BANK OF AFRICA | P122: BMCE CAPITAL GESTION | Q122: 3.5469585e+09 | R122: 2369.29 | S122: -0.002476 | T122: - | U122: -0.002194 | V122: 0.001628 | W122: 0.00769 | X122: 0.01154 | Y122: -0.01677 | Z122: 0.095671 | AA122: 0.222922 | AB122: 0.165829
A123: MA0000036402 | B123: 3640 | C123: UPLINE EQUILIBRE | D123: UPLINE CAPITAL MANAGEMENT | E123: FCP | F123: DIVERSIFIÉ | G123: - | H123: 75% MBI GLOBAL + 25% MASI 20 | I123: QUOTIDIENNE | J123: FNPP | K123: MIXTE | L123: 0 | M123: 0 | N123: 0.02 | O123: BCP | P123: UPLINE CAPITAL MANAGEMENT | Q123: 5.6890334e+08 | R123: 124.58 | S123: 0.005423 | T123: - | U123: -0.003758 | V123: -0.002163 | W123: 0.01806 | X123: 0.059711 | Y123: -0.048256 | Z123: 0.190374 | AA123: -0.050326 | AB123: -0.086258
A124: MA0000036436 | B124: 3643 | C124: EMERGENCE CAPITAL | D124: VALORIS MANAGEMENT | E124: FCP | F124: OMLT | G124: [1,1 5,1[ | H124: MBI GLOBAL | I124: HEBDOMADAIRE | J124: FGP | K124: CAPITALISANT | L124: 0.03 | M124: 0.015 | N124: 0.005 | O124: BANK OF AFRICA | P124: VALORIS MANAGEMENT | Q124: 273288824 | R124: 1799.38 | S124: 0.005134 | T124: - | U124: -0.000983 | V124: 0.001737 | W124: 0.005549 | X124: 0.007452 | Y124: 0.0046 | Z124: 0.059269 | AA124: 0.127834 | AB124: 0.110242
A125: MA0000036444 | B125: 3644 | C125: AL IJTIMAI PATRIMOINE | D125: VALORIS MANAGEMENT | E125: FCP | F125: OMLT | G125: [1,1 7,1[ | H125: MBI GLOBAL | I125: HEBDOMADAIRE | J125: FNPP | K125: CAPITALISANT | L125: 0.03 | M125: 0.015 | N125: 0.008 | O125: CDG | P125: VALORIS MANAGEMENT | Q125: 5.0522233e+09 | R125: 214395.21 | S125: 0.005001 | T125: - | U125: 0.002374 | V125: 0.006 | W125: 0.011711 | X125: 0.013192 | Y125: -0.006166 | Z125: 0.093309 | AA125: 0.216864 | AB125: 0.139554
A126: MA0000036485 | B126: 3648 | C126: CAT ACTIONS | D126: CIH CAPITAL MANAGEMENT | E126: FCP | F126: ACTIONS | G126: - | H126: MASI RN | I126: HEBDOMADAIRE | J126: FNPP | K126: DISTRIBUANT | L126: 0 | M126: 0 | N126: 0.02 | O126: BMCI | P126: CIH CAPITAL MANAGEMENT | Q126: 2.8936775e+08 | R126: 505887.68 | S126: 0.029563 | T126: - | U126: 0.013873 | V126: 0.018435 | W126: 0.059921 | X126: 0.123787 | Y126: -0.066276 | Z126: 0.376374 | AA126: 0.6044 | AB126: 0.573048
A127: MA0000036493 | B127: 3649 | C127: FCP CAPITAL MAGHREB | D127: BMCE CAPITAL GESTION | E127: FCP | F127: ACTIONS | G127: - | H127: MASI | I127: QUOTIDIENNE | J127: FGP | K127: CAPITALISANT | L127: 0.02 | M127: 0.02 | N127: 0.02 | O127: BANK OF AFRICA | P127: BMCE CAPITAL GESTION | Q127: 1.4984234e+09 | R127: 1795.48 | S127: 0.009735 | T127: - | U127: -0.00643 | V127: -0.003303 | W127: 0.037232 | X127: 0.117405 | Y127: -0.098682 | Z127: 0.377715 | AA127: 0.725394 | AB127: 0.62907
A128: MA0000036501 | B128: 3650 | C128: FCP CAPITAL MULTI-GESTION | D128: BMCE CAPITAL GESTION | E128: FCP | F128: DIVERSIFIÉ | G128: - | H128: 80% MBI GLOBAL + 20% MASI | I128: QUOTIDIENNE | J128: FGP | K128: CAPITALISANT | L128: 0.02 | M128: 0.02 | N128: 0.02 | O128: BANK OF AFRICA | P128: BMCE CAPITAL GESTION | Q128: 1.7376967e+09 | R128: 544.36 | S128: -0.016211 | T128: - | U128: -0.003077 | V128: -0.001266 | W128: 0.013253 | X128: 0.030224 | Y128: -0.061739 | Z128: 0.130762 | AA128: 0.266101 | AB128: 0.170339
A129: MA0000036519 | B129: 3651 | C129: FCP AL IJTIMAI SECURITE | D129: BMCE CAPITAL GESTION | E129: FCP | F129: OMLT | G129: [1,1 7[ | H129: MBI GLOBAL | I129: HEBDOMADAIRE | J129: FNPP | K129: CAPITALISANT | L129: 0.03 | M129: 0.015 | N129: 0.02 | O129: BANK OF AFRICA | P129: BMCE CAPITAL GESTION | Q129: 3.0176673e+09 | R129: 225047.9 | S129: -0.003419 | T129: - | U129: -0.001662 | V129: 0.001546 | W129: 0.005532 | X129: 0.007169 | Y129: -0.017863 | Z129: 0.084594 | AA129: 0.206594 | AB129: 0.149922
...

Sheet 28_08
A1: Tableau des performances hebdomadaires au 28-08-2026
A2: CODE ISIN | B2: Code Maroclear | C2: OPCVM | D2: Société de Gestion | E2: Nature juridique | F2: Classification | G2: Sensibilité | H2: Indice Bentchmark | I2: Périodicité VL | J2: Souscripteurs | K2: Affectation des résultats | L2: Commission de souscription | M2: Commission de rachat | N2: Frais de gestion | O2: Dépositaire | P2: Réseau placeur | Q2: AN | R2: VL | S2: YTD | T2: 1 jour | U2: 1 semaine | V2: 1 mois | W2: 3 mois | X2: 6 mois | Y2: 1 an | Z2: 2 ans | AA2: 3 ans | AB2: 5 ans
A3: MA0000030058 | B3: 3005 | C3: BMCI COSMOS | D3: CIH CAPITAL MANAGEMENT | E3: SICAV | F3: ACTIONS | G3: - | H3: MASI | I3: HEBDOMADAIRE | J3: FGP | K3: CAPITALISANT | L3: 0.02 | M3: 0.0075 | N3: 0.02 | O3: BMCI | P3: CIH CAPITAL MANAGEMENT | Q3: 30059592 | R3: 448.19 | S3: 0.027841 | T3: - | U3: -0.009875 | V3: 0.062137 | W3: 0.025395 | X3: 0.0592 | Y3: -0.077912 | Z3: 0.369648 | AA3: 0.590849 | AB3: 0.523316
A4: MA0000030066 | B4: 3006 | C4: BMCI EPARGNE OBLIGATIONS | D4: CIH CAPITAL MANAGEMENT | E4: SICAV | F4: OMLT | G4: [3 7[ | H4: MBI MLT | I4: HEBDOMADAIRE | J4: FGP | K4: CAPITALISANT | L4: 0.005 | M4: 0.0025 | N4: 0.0093 | O4: BMCI | P4: CIH CAPITAL MANAGEMENT | Q4: 1.1630302e+08 | R4: 274.67 | S4: -0.007301 | T4: - | U4: 0.000692 | V4: 0.004462 | W4: 0.001166 | X4: -0.005827 | Y4: -0.010519 | Z4: 0.067758 | AA4: 0.160708 | AB4: 0.092953
A5: MA0000030132 | B5: 3013 | C5: BMCI TRESORERIE | D5: CIH CAPITAL MANAGEMENT | E5: SICAV | F5: MONÉTAIRE | G5: [0 0,5[ | H5: TMJ(jj) | I5: QUOTIDIENNE | J5: FGP | K5: CAPITALISANT | L5: 0.0125 | M5: 0.005 | N5: 0.0195 | O5: BMCI | P5: CIH CAPITAL MANAGEMENT | Q5: 1.6672222e+08 | R5: 123497.94 | S5: 0.01033 | T5: - | U5: 0.000154 | V5: 0.001165 | W5: 0.003663 | X5: 0.007657 | Y5: 0.015108 | Z5: 0.033071 | AA5: 0.056927 | AB5: 0.083851
A6: MA0000030215 | B6: 3021 | C6: CDG IZDIHAR | D6: CDG CAPITAL GESTION | E6: SICAV | F6: DIVERSIFIÉ | G6: - | H6: 77% MBI GLOBAL + 23% CFG 25 FLOTTANT | I6: HEBDOMADAIRE | J6: FGP | K6: CAPITALISANT | L6: 0.003 | M6: 0.0025 | N6: 0.02 | O6: CDG CAPITAL | P6: CDG CAPITAL GESTION | Q6: 1.3111562e+09 | R6: 4148.32 | S6: -0.03392 | T6: - | U6: -0.00333 | V6: 0.029822 | W6: 0.006862 | X6: -0.01927 | Y6: -0.094073 | Z6: 0.130588 | AA6: 0.273811 | AB6: 0.182268
A7: MA0000030280 | B7: 3028 | C7: CDG TAWFIR | D7: CDG CAPITAL GESTION | E7: SICAV | F7: OMLT | G7: [3 7[ | H7: MBI GLOBAL | I7: QUOTIDIENNE | J7: FGP | K7: CAPITALISANT | L7: 0.005 | M7: 0 | N7: 0.02 | O7: CDG CAPITAL | P7: CDG CAPITAL GESTION | Q7: 1.7862818e+09 | R7: 3480.13 | S7: 0.000725 | T7: - | U7: 0.001059 | V7: 0.007825 | W7: 0.004979 | X7: 0.000106 | Y7: -0.005001 | Z7: 0.080306 | AA7: 0.171438 | AB7: 0.10606
A8: MA0000030298 | B8: 3029 | C8: SICAV OBLIGATIONS PÉRENNITÉ | D8: CDG CAPITAL GESTION | E8: SICAV | F8: OMLT | G8: [1,1 16[ | H8: MBI MT | I8: QUOTIDIENNE | J8: FNPP | K8: CAPITALISANT | L8: 0.03 | M8: 0.015 | N8: 0.02 | O8: CDG CAPITAL | P8: CDG CAPITAL GESTION | Q8: 7.6482153e+09 | R8: 3303.39 | S8: -0.003731 | T8: - | U8: 0.001382 | V8: 0.003573 | W8: 0.005574 | X8: 0.006024 | Y8: -0.002211 | Z8: 0.051881 | AA8: 0.106567 | AB8: 0.120351
A9: MA0000030306 | B9: 3030 | C9: CDG TRESORERIE | D9: CDG CAPITAL GESTION | E9: SICAV | F9: MONÉTAIRE | G9: [0 0,5[ | H9: 50% MBI CT + 50% TMP | I9: QUOTIDIENNE | J9: FGP | K9: CAPITALISANT | L9: 0 | M9: 0 | N9: 0.02 | O9: CDG CAPITAL | P9: CDG CAPITAL GESTION | Q9: 4.9557964e+09 | R9: 2279.19 | S9: 0.018387 | T9: - | U9: 0.000272 | V9: 0.002362 | W9: 0.006616 | X9: 0.01405 | Y9: 0.026792 | Z9: 0.056952 | AA9: 0.093987 | AB9: 0.138292
A10: MA0000030363 | B10: 3036 | C10: BMCI EPARGNE CROISSANCE | D10: CIH CAPITAL MANAGEMENT | E10: SICAV | F10: DIVERSIFIÉ | G10: - | H10: 60% MASI + 40% MBI MT | I10: HEBDOMADAIRE | J10: FGP | K10: CAPITALISANT | L10: 0.0125 | M10: 0.005 | N10: 0.0195 | O10: BMCI | P10: CIH CAPITAL MANAGEMENT | Q10: 2.6922323e+08 | R10: 165.44 | S10: -0.016058 | T10: - | U10: -0.002292 | V10: 0.020353 | W10: 0.009334 | X10: -0.001268 | Y10: -0.046455 | Z10: 0.137123 | AA10: 0.269198 | AB10: 0.274282
A11: MA0000030371 | B11: 3037 | C11: CIMR TRESO PLUS | D11: SAHAM CAPITAL GESTION | E11: SICAV | F11: OCT | G11: ]0,5 1,1] | H11: MBI CT | I11: QUOTIDIENNE | J11: FNPP | K11: CAPITALISANT | L11: 0 | M11: 0 | N11: 0.02 | O11: SAHAM BANK | P11: SAHAM BANK | Q11: 1.3708945e+08 | R11: 403204.27 | S11: 0.016246 | T11: - | U11: 0.000278 | V11: 0.001997 | W11: 0.005877 | X11: 0.012101 | Y11: 0.021817 | Z11: 0.051166 | AA11: 0.089102 | AB11: 0.132216
A12: MA0000030397 | B12: 3039 | C12: CDG BARID | D12: CDG CAPITAL GESTION | E12: SICAV | F12: OMLT | G12: [3 7[ | H12: - | I12: HEBDOMADAIRE | J12: FNPP | K12: CAPITALISANT | L12: 0.005 | M12: 0 | N12: 0.02 | O12: CDG | P12: CDG CAPITAL GESTION | Q12: 3404328173 | R12: 3736.34 | S12: -0.005025 | T12: - | U12: 0.000753 | V12: 0.007608 | W12: 0.004611 | X12: -0.002587 | Y12: -0.015569 | Z12: 0.080082 | AA12: 0.185601 | AB12: 0.077379
A13: MA0000030405 | B13: 3040 | C13: SICAV MAROC CROISSANCE | D13: MAROGEST | E13: SICAV | F13: DIVERSIFIÉ | G13: - | H13: - | I13: HEBDOMADAIRE | J13: FGP | K13: CAPITALISANT | L13: 0.02 | M13: 0.005 | N13: 0.02 | O13: CIH BANK | P13: MAROGEST | Q13: 3.0593642e+08 | R13: 5213.64 | S13: -0.038709 | T13: - | U13: -0.003492 | V13: 0.027268 | W13: 0.019783 | X13: -0.015609 | Y13: -0.099284 | Z13: 0.149024 | AA13: 0.351234 | AB13: 0.33887
A14: MA0000030413 | B14: 3041 | C14: BMCI CASH | D14: CIH CAPITAL MANAGEMENT | E14: SICAV | F14: OCT | G14: [0,6 1,1[ | H14: MBI CT | I14: QUOTIDIENNE | J14: FGP | K14: CAPITALISANT | L14: 0 | M14: 0 | N14: 0.0067 | O14: BMCI | P14: CIH CAPITAL MANAGEMENT | Q14: 31370990 | R14: 196.53 | S14: 0.02136 | T14: - | U14: 0.000407 | V14: 0.004857 | W14: 0.007743 | X14: 0.018396 | Y14: 0.032087 | Z14: 0.063301 | AA14: 0.094021 | AB14: 0.116077
... A57: MA0000035453 | B57: 3545 | C57: SCR INTEGRALE | D57: CDG CAPITAL GESTION | E57: FCP | F57: ACTIONS | G57: - | H57: CFG 25 FLOTTANT | I57: HEBDOMADAIRE | J57: FNPP | K57: DISTRIBUANT | L57: 0.03 | M57: 0.015 | N57: 0.02 | O57: CDG CAPITAL | P57: CDG CAPITAL GESTION | Q57: 2.2849113e+08 | R57: 6636.97 | S57: -0.046074 | T57: - | U57: -0.007946 | V57: 0.057585 | W57: 0.025991 | X57: 0.011195 | Y57: -0.136093 | Z57: 0.271175 | AA57: 0.491041 | AB57: 0.414498
A58: MA0000035461 | B58: 3546 | C58: SCR OBLIGATIONS | D58: CDG CAPITAL GESTION | E58: FCP | F58: OMLT | G58: ]1,1 9] | H58: MBI GLOBAL | I58: HEBDOMADAIRE | J58: FNPP | K58: CAPITALISANT | L58: 0 | M58: 0 | N58: - | O58: CDG CAPITAL | P58: CDG CAPITAL GESTION | Q58: 2.4233819e+09 | R58: 2734.15 | S58: -0.000314 | T58: - | U58: 0.001021 | V58: 0.004896 | W58: 0.004873 | X58: -0.000215 | Y58: -0.005781 | Z58: 0.081221 | AA58: 0.184158 | AB58: 0.081585
A59: MA0000035487 | B59: 3548 | C59: CDG ACTIONS | D59: CDG CAPITAL GESTION | E59: FCP | F59: ACTIONS | G59: - | H59: CFG 25 FLOTTANT | I59: HEBDOMADAIRE | J59: FNPP | K59: CAPITALISANT | L59: 0.03 | M59: 0.015 | N59: 0.02 | O59: CDG CAPITAL | P59: CDG CAPITAL GESTION | Q59: 1.7754131e+09 | R59: 7699.36 | S59: -0.023814 | T59: - | U59: -0.009618 | V59: 0.064281 | W59: 0.032857 | X59: 0.030486 | Y59: -0.122024 | Z59: 0.237715 | AA59: 0.409457 | AB59: 0.3516
A60: MA0000035495 | B60: 3549 | C60: AL IKRAM | D60: CIH CAPITAL MANAGEMENT | E60: FCP | F60: DIVERSIFIÉ | G60: - | H60: 60% MASI + 40% MBI MT | I60: HEBDOMADAIRE | J60: FNPP | K60: CAPITALISANT | L60: 0.03 | M60: 0.015 | N60: 0.0075 | O60: BMCI | P60: CIH CAPITAL MANAGEMENT | Q60: 35009545 | R60: 36852.15 | S60: -0.000594 | T60: - | U60: 6.7e-05 | V60: 0.014647 | W60: 0.010182 | X60: 0.012357 | Y60: -0.025537 | Z60: 0.123481 | AA60: 0.234668 | AB60: 0.255275
A61: MA0000035503 | B61: 3550 | C61: CASACTIONS | D61: CIH CAPITAL MANAGEMENT | E61: FCP | F61: DIVERSIFIÉ | G61: - | H61: 80% MBI GLOBAL + 20% MASI | I61: HEBDOMADAIRE | J61: FNPP | K61: DISTRIBUANT | L61: 0.03 | M61: 0.015 | N61: 0.02 | O61: BMCI | P61: CIH CAPITAL MANAGEMENT | Q61: 2472456.7 | R61: 176604.05 | S61: 0.000654 | T61: - | U61: 0.000529 | V61: 0.00282 | W61: 0.002963 | X61: 0.002556 | Y61: -0.00143 | Z61: 0.010906 | AA61: 0.032505 | AB61: 0.032218
A62: MA0000035511 | B62: 3551 | C62: AVENIR ACTIONS | D62: CIH CAPITAL MANAGEMENT | E62: FCP | F62: DIVERSIFIÉ | G62: - | H62: 80% MBI GLOBAL + 20% MASI | I62: HEBDOMADAIRE | J62: FNPP | K62: DISTRIBUANT | L62: 0.03 | M62: 0.015 | N62: 0.02 | O62: BMCI | P62: CIH CAPITAL MANAGEMENT | Q62: 2.2552901e+08 | R62: 249478.99 | S62: -0.001505 | T62: - | U62: -0.003695 | V62: 0.02463 | W62: 0.011255 | X62: 0.012772 | Y62: -0.047082 | Z62: 0.13284 | AA62: 0.251502 | AB62: 0.244117
A63: MA0000035529 | B63: 3552 | C63: AXA HORIZON | D63: CIH CAPITAL MANAGEMENT | E63: FCP | F63: DIVERSIFIÉ | G63: - | H63: CFG 25 FLOTTANT | I63: HEBDOMADAIRE | J63: FNPP | K63: MIXTE | L63: 0.03 | M63: 0.015 | N63: 0 | O63: BMCI | P63: CIH CAPITAL MANAGEMENT | Q63: 8.2312574e+08 | R63: 181185.5 | S63: 0.008685 | T63: - | U63: -0.001721 | V63: 0.02342 | W63: 0.01131 | X63: 0.015469 | Y63: -0.025224 | Z63: 0.189874 | AA63: 0.333621 | AB63: 0.29179
A64: MA0000035537 | B64: 3553 | C64: CIMR THARWA | D64: CIH CAPITAL MANAGEMENT | E64: FCP | F64: ACTIONS | G64: - | H64: MASI RN | I64: HEBDOMADAIRE | J64: FNPP | K64: CAPITALISANT | L64: 0 | M64: 0 | N64: 0.02 | O64: BMCI | P64: CIH CAPITAL MANAGEMENT | Q64: 1.1534852e+09 | R64: 519120.27 | S64: 0.029033 | T64: - | U64: -0.01047 | V64: 0.064866 | W64: 0.023985 | X64: 0.060736 | Y64: -0.065596 | Z64: 0.388493 | AA64: 0.644857 | AB64: 0.646837
A65: MA0000035545 | B65: 3554 | C65: BMCI INVEST | D65: CIH CAPITAL MANAGEMENT | E65: FCP | F65: DIVERSIFIÉ | G65: - | H65: 60% MASI + 40% MBI MT | I65: HEBDOMADAIRE | J65: FNPP | K65: CAPITALISANT | L65: 0.03 | M65: 0.015 | N65: 0.006 | O65: BMCI | P65: CIH CAPITAL MANAGEMENT | Q65: 837408.87 | R65: 239.26 | S65: 0.00243 | T65: - | U65: -0.00246 | V65: 0.008855 | W65: -0.011649 | X65: -0.002917 | Y65: -0.014296 | Z65: 0.041937 | AA65: 0.065556 | AB65: 0.059282
A66: MA0000035552 | B66: 3555 | C66: AXA AVENIR | D66: CDG CAPITAL GESTION | E66: FCP | F66: DIVERSIFIÉ | G66: - | H66: 80% MBI GLOBAL + 25% MASI RN | I66: HEBDOMADAIRE | J66: FNPP | K66: MIXTE | L66: 0.03 | M66: 0.015 | N66: 0.02 | O66: CDG CAPITAL | P66: CDG CAPITAL GESTION | Q66: 7.8159914e+08 | R66: 3654.27 | S66: -0.017477 | T66: - | U66: -0.001626 | V66: 0.022857 | W66: 0.012302 | X66: 0.000803 | Y66: -0.060437 | Z66: 0.142865 | AA66: 0.253722 | AB66: 0.197511
A67: MA0000035594 | B67: 3559 | C67: HORIZON BALANCED FUND | D67: SAHAM CAPITAL GESTION | E67: FCP | F67: DIVERSIFIÉ | G67: - | H67: 50% MBI GLOBAL + 50% MASI | I67: QUOTIDIENNE | J67: FGP | K67: DISTRIBUANT | L67: 0.02 | M67: 0.015 | N67: 0.02 | O67: SAHAM BANK | P67: SAHAM BANK | Q67: 1288282.7 | R67: 107356.89 | S67: -0.005531 | T67: - | U67: -0.004107 | V67: 0.027485 | W67: -0.024732 | X67: 0.002693 | Y67: -0.055787 | Z67: 0.178758 | AA67: 0.356765 | AB67: 0.373956
A68: MA0000035651 | B68: 3565 | C68: ATLAS PREMIUM | D68: ATLAS CAPITAL MANAGEMENT | E68: FCP | F68: ACTIONS | G68: - | H68: MASI | I68: HEBDOMADAIRE | J68: FGP | K68: CAPITALISANT | L68: 0.03 | M68: 0.015 | N68: 0.015 | O68: CIH BANK | P68: ATLAS CAPITAL MANAGEMENT | Q68: 1043235 | R68: 760.92 | S68: 0.041671 | T68: - | U68: -0.009103 | V68: 0.061285 | W68: 0.029313 | X68: 0.071673 | Y68: -0.058384 | Z68: 0.425985 | AA68: 0.69022 | AB68: 0.633471
A69: MA0000035677 | B69: 3567 | C69: CDG HORIZONS | D69: CDG CAPITAL GESTION | E69: FCP | F69: OMLT | G69: ]1,1 5,1] | H69: 50% MBI MLT + 50% MBI MT | I69: QUOTIDIENNE | J69: FGP | K69: CAPITALISANT | L69: 0.03 | M69: 0.015 | N69: 0.02 | O69: CDG CAPITAL | P69: CDG CAPITAL GESTION | Q69: 2.3093372e+08 | R69: 2259.73 | S69: 0.008245 | T69: - | U69: 0.001187 | V69: 0.004302 | W69: 0.005621 | X69: 0.006785 | Y69: 0.014501 | Z69: 0.082588 | AA69: 0.143877 | AB69: 0.132118
A70: MA0000035685 | B70: 3568 | C70: AVENIR OBLIGATION | D70: CFG GESTION | E70: FCP | F70: OMLT | G70: [4 8[ | H70: CFG BONDS MT | I70: HEBDOMADAIRE | J70: FNPP | K70: MIXTE | L70: 0 | M70: 0 | N70: 0.01 | O70: ATTIJARIWAFA BANK | P70: CFG GESTION | Q70: 1.4030124e+09 | R70: 26125.89 | S70: -0.00212 | T70: - | U70: 0.000587 | V70: 0.002894 | W70: 0.001978 | X70: -0.003436 | Y70: -0.011381 | Z70: 0.076156 | AA70: 0.181095 | AB70: 0.087739
... A118: MA0000036329 | B118: 3632 | C118: FCP CAPITAL TERME | D118: BMCE CAPITAL GESTION | E118: FCP | F118: DIVERSIFIÉ | G118: - | H118: 80% MBI GLOBAL + 20% MASI | I118: QUOTIDIENNE | J118: FGP | K118: CAPITALISANT | L118: 0.02 | M118: 0.02 | N118: 0.02 | O118: BANK OF AFRICA | P118: BMCE CAPITAL GESTION | Q118: 81163921 | R118: 248.49 | S118: 0.023519 | T118: - | U118: -0.002249 | V118: 0.015779 | W118: 0.024321 | X118: 0.030352 | Y118: -0.005244 | Z118: 0.171183 | AA118: 0.29943 | AB118: 0.253038
A119: MA0000036345 | B119: 3634 | C119: CFG INSTIBONDS | D119: CFG GESTION | E119: FCP | F119: OMLT | G119: ]1,5 5,5] | H119: MBI GLOBAL | I119: QUOTIDIENNE | J119: FGP | K119: CAPITALISANT | L119: 0.03 | M119: 0.015 | N119: 0.02 | O119: CFG BANK | P119: CFG GESTION; CFG BANK | Q119: 5.5306098e+08 | R119: 34.19 | S119: 0.002933 | T119: - | U119: 0.001171 | V119: 0.004702 | W119: 0.004112 | X119: -0.00146 | Y119: -0.779916 | Z119: -0.767304 | AA119: -0.754823 | AB119: -
A120: MA0000036352 | B120: 3635 | C120: FCP CAM TRESO PLUS | D120: MAROGEST | E120: FCP | F120: OCT | G120: ]0,5 1,1] | H120: 85% MBI CT + 15 % MBI MT | I120: QUOTIDIENNE | J120: FGP | K120: CAPITALISANT | L120: 0.03 | M120: 0.015 | N120: 0.02 | O120: CIH BANK | P120: CIH | Q120: 8.8574952e+08 | R120: 174.82 | S120: 0.019061 | T120: - | U120: 0.000458 | V120: 0.002466 | W120: 0.00668 | X120: 0.014155 | Y120: 0.026481 | Z120: 0.062413 | AA120: 0.105476 | AB120: 0.152102
A121: MA0000036378 | B121: 3637 | C121: AVENIR CROISSANCE | D121: CFG GESTION | E121: FCP | F121: ACTIONS | G121: - | H121: CFG 25 FLOTTANT | I121: HEBDOMADAIRE | J121: FNPP | K121: MIXTE | L121: 0.03 | M121: 0.015 | N121: 0.02 | O121: ATTIJARIWAFA BANK | P121: CFG GESTION | Q121: 1301988.9 | R121: 36166.36 | S121: -0.035743 | T121: - | U121: -0.004215 | V121: 0.034883 | W121: 0.018223 | X121: -0.004291 | Y121: -0.117829 | Z121: 0.207055 | AA121: 0.451031 | AB121: 0.437278
A122: MA0000036394 | B122: 3639 | C122: FCP CAPITAL TAALIM | D122: BMCE CAPITAL GESTION | E122: FCP | F122: OMLT | G122: [4 8[ | H122: 95% MBI MLT + 5% MASI | I122: HEBDOMADAIRE | J122: FNPP | K122: CAPITALISANT | L122: 0.03 | M122: 0.015 | N122: 0.02 | O122: BANK OF AFRICA | P122: BMCE CAPITAL GESTION | Q122: 3.5547497e+09 | R122: 2374.5 | S122: -0.000282 | T122: - | U122: 0.000362 | V122: 0.008404 | W122: 0.005428 | X122: 0.001121 | Y122: -0.014031 | Z122: 0.104927 | AA122: 0.225915 | AB122: 0.16963
A123: MA0000036402 | B123: 3640 | C123: UPLINE EQUILIBRE | D123: UPLINE CAPITAL MANAGEMENT | E123: FCP | F123: DIVERSIFIÉ | G123: - | H123: 75% MBI GLOBAL + 25% MASI 20 | I123: QUOTIDIENNE | J123: FNPP | K123: MIXTE | L123: 0 | M123: 0 | N123: 0.02 | O123: BCP | P123: UPLINE CAPITAL MANAGEMENT | Q123: 5.7104715e+08 | R123: 125.05 | S123: 0.009216 | T123: - | U123: -0.004141 | V123: 0.028626 | W123: 0.010832 | X123: 0.026504 | Y123: -0.044665 | Z123: 0.206163 | AA123: -0.046397 | AB123: -0.082875
A124: MA0000036436 | B124: 3643 | C124: EMERGENCE CAPITAL | D124: VALORIS MANAGEMENT | E124: FCP | F124: OMLT | G124: [1,1 5,1[ | H124: MBI GLOBAL | I124: HEBDOMADAIRE | J124: FGP | K124: CAPITALISANT | L124: 0.03 | M124: 0.015 | N124: 0.005 | O124: BANK OF AFRICA | P124: VALORIS MANAGEMENT | Q124: 2.7355827e+08 | R124: 1801.15 | S124: 0.006122 | T124: - | U124: 0.000767 | V124: 0.00313 | W124: 0.005173 | X124: 0.004461 | Y124: 0.006032 | Z124: 0.063315 | AA124: 0.129722 | AB124: 0.11156
A125: MA0000036444 | B125: 3644 | C125: AL IJTIMAI PATRIMOINE | D125: VALORIS MANAGEMENT | E125: FCP | F125: OMLT | G125: [1,1 7,1[ | H125: MBI GLOBAL | I125: HEBDOMADAIRE | J125: FNPP | K125: CAPITALISANT | L125: 0.03 | M125: 0.015 | N125: 0.008 | O125: CDG | P125: VALORIS MANAGEMENT | Q125: 5.0402563e+09 | R125: 213887.39 | S125: 0.002621 | T125: - | U125: 0.000429 | V125: 0.006832 | W125: 0.005676 | X125: 0.002966 | Y125: -0.007824 | Z125: 0.097847 | AA125: 0.214907 | AB125: 0.136954
A126: MA0000036485 | B126: 3648 | C126: CAT ACTIONS | D126: CIH CAPITAL MANAGEMENT | E126: FCP | F126: ACTIONS | G126: - | H126: MASI RN | I126: HEBDOMADAIRE | J126: FNPP | K126: DISTRIBUANT | L126: 0 | M126: 0 | N126: 0.02 | O126: BMCI | P126: CIH CAPITAL MANAGEMENT | Q126: 2.907318e+08 | R126: 508272.37 | S126: 0.015476 | T126: - | U126: -0.010232 | V126: 0.062833 | W126: 0.024885 | X126: 0.044927 | Y126: -0.081622 | Z126: 0.357726 | AA126: 0.565456 | AB126: 0.549467
A127: MA0000036493 | B127: 3649 | C127: FCP CAPITAL MAGHREB | D127: BMCE CAPITAL GESTION | E127: FCP | F127: ACTIONS | G127: - | H127: MASI | I127: QUOTIDIENNE | J127: FGP | K127: CAPITALISANT | L127: 0.02 | M127: 0.02 | N127: 0.02 | O127: BANK OF AFRICA | P127: BMCE CAPITAL GESTION | Q127: 1.5134673e+09 | R127: 1807.1 | S127: 0.01627 | T127: - | U127: -0.010041 | V127: 0.063713 | W127: 0.020937 | X127: 0.051783 | Y127: -0.092014 | Z127: 0.392455 | AA127: 0.714825 | AB127: 0.633921
A128: MA0000036501 | B128: 3650 | C128: FCP CAPITAL MULTI-GESTION | D128: BMCE CAPITAL GESTION | E128: FCP | F128: DIVERSIFIÉ | G128: - | H128: 80% MBI GLOBAL + 20% MASI | I128: QUOTIDIENNE | J128: FGP | K128: CAPITALISANT | L128: 0.02 | M128: 0.02 | N128: 0.02 | O128: BANK OF AFRICA | P128: BMCE CAPITAL GESTION | Q128: 1.7541006e+09 | R128: 546.04 | S128: -0.013175 | T128: - | U128: -0.002466 | V128: 0.022375 | W128: 0.006395 | X128: 0.002884 | Y128: -0.058194 | Z128: 0.14053 | AA128: 0.268268 | AB128: 0.173296
A129: MA0000036519 | B129: 3651 | C129: FCP AL IJTIMAI SECURITE | D129: BMCE CAPITAL GESTION | E129: FCP | F129: OMLT | G129: [1,1 7[ | H129: MBI GLOBAL | I129: HEBDOMADAIRE | J129: FNPP | K129: CAPITALISANT | L129: 0.03 | M129: 0.015 | N129: 0.02 | O129: BANK OF AFRICA | P129: BMCE CAPITAL GESTION | Q129: 3.0226897e+09 | R129: 225422.45 | S129: -0.001761 | T129: - | U129: 0.000367 | V129: 0.007496 | W129: 0.003587 | X129: -0.000614 | Y129: -0.015649 | Z129: 0.093923 | AA129: 0.209737 | AB129: 0.151964
...

Sheet 24_08
A1: Tableau des performances hebdomadaires au 24-08-2026
A2: CODE ISIN | B2: Code Maroclear | C2: OPCVM | D2: Société de Gestion | E2: Nature juridique | F2: Classification | G2: Sensibilité | H2: Indice Bentchmark | I2: Périodicité VL | J2: Souscripteurs | K2: Affectation des résultats | L2: Commission de souscription | M2: Commission de rachat | N2: Frais de gestion | O2: Dépositaire | P2: Réseau placeur | Q2: AN | R2: VL | S2: YTD | T2: 1 jour | U2: 1 semaine | V2: 1 mois | W2: 3 mois | X2: 6 mois | Y2: 1 an | Z2: 2 ans | AA2: 3 ans | AB2: 5 ans
A3: MA0000030058 | B3: 3005 | C3: BMCI COSMOS | D3: CIH CAPITAL MANAGEMENT | E3: SICAV | F3: ACTIONS | G3: - | H3: MASI | I3: HEBDOMADAIRE | J3: FGP | K3: CAPITALISANT | L3: 0.02 | M3: 0.0075 | N3: 0.02 | O3: BMCI | P3: CIH CAPITAL MANAGEMENT | Q3: 30359266 | R3: 452.66 | S3: 0.038092 | T3: - | U3: 0.015707 | V3: 0.078019 | W3: 0.063806 | X3: 0.035196 | Y3: -0.065852 | Z3: 0.384027 | AA3: 0.603983 | AB3: 0.548614
A4: MA0000030066 | B4: 3006 | C4: BMCI EPARGNE OBLIGATIONS | D4: CIH CAPITAL MANAGEMENT | E4: SICAV | F4: OMLT | G4: [3 7[ | H4: MBI MLT | I4: HEBDOMADAIRE | J4: FGP | K4: CAPITALISANT | L4: 0.005 | M4: 0.0025 | N4: 0.0093 | O4: BMCI | P4: CIH CAPITAL MANAGEMENT | Q4: 1.1637948e+08 | R4: 274.48 | S4: -0.007987 | T4: - | U4: 0.001204 | V4: 0.004281 | W4: 0.001642 | X4: -0.006623 | Y4: -0.010812 | Z4: 0.070974 | AA4: 0.160101 | AB4: 0.091893
A5: MA0000030132 | B5: 3013 | C5: BMCI TRESORERIE | D5: CIH CAPITAL MANAGEMENT | E5: SICAV | F5: MONÉTAIRE | G5: [0 0,5[ | H5: TMJ(jj) | I5: QUOTIDIENNE | J5: FGP | K5: CAPITALISANT | L5: 0.0125 | M5: 0.005 | N5: 0.0195 | O5: BMCI | P5: CIH CAPITAL MANAGEMENT | Q5: 1.6793136e+08 | R5: 123478.94 | S5: 0.010174 | T5: - | U5: 0.000319 | V5: 0.001243 | W5: 0.003902 | X5: 0.007801 | Y5: 0.014992 | Z5: 0.033321 | AA5: 0.057219 | AB5: 0.083757
A6: MA0000030215 | B6: 3021 | C6: CDG IZDIHAR | D6: CDG CAPITAL GESTION | E6: SICAV | F6: DIVERSIFIÉ | G6: - | H6: 77% MBI GLOBAL + 23% CFG 25 FLOTTANT | I6: HEBDOMADAIRE | J6: FGP | K6: CAPITALISANT | L6: 0.003 | M6: 0.0025 | N6: 0.02 | O6: CDG CAPITAL | P6: CDG CAPITAL GESTION | Q6: 1.3155362e+09 | R6: 4162.18 | S6: -0.030692 | T6: - | U6: 0.005132 | V6: 0.036443 | W6: 0.019765 | X6: -0.034151 | Y6: -0.093387 | Z6: 0.135957 | AA6: 0.276445 | AB6: 0.189878
A7: MA0000030280 | B7: 3028 | C7: CDG TAWFIR | D7: CDG CAPITAL GESTION | E7: SICAV | F7: OMLT | G7: [3 7[ | H7: MBI GLOBAL | I7: QUOTIDIENNE | J7: FGP | K7: CAPITALISANT | L7: 0.005 | M7: 0 | N7: 0.02 | O7: CDG CAPITAL | P7: CDG CAPITAL GESTION | Q7: 1.7843932e+09 | R7: 3476.45 | S7: -0.000334 | T7: - | U7: 0.0014 | V7: 0.007427 | W7: 0.005874 | X7: -0.002239 | Y7: -0.00651 | Z7: 0.084067 | AA7: 0.170577 | AB7: 0.104599
A8: MA0000030298 | B8: 3029 | C8: SICAV OBLIGATIONS PÉRENNITÉ | D8: CDG CAPITAL GESTION | E8: SICAV | F8: OMLT | G8: [1,1 16[ | H8: MBI MT | I8: QUOTIDIENNE | J8: FNPP | K8: CAPITALISANT | L8: 0.03 | M8: 0.015 | N8: 0.02 | O8: CDG CAPITAL | P8: CDG CAPITAL GESTION | Q8: 8.1706182e+09 | R8: 3298.83 | S8: -0.005106 | T8: - | U8: 0.000752 | V8: 0.002413 | W8: 0.005465 | X8: 0.005364 | Y8: -0.003272 | Z8: 0.053741 | AA8: 0.106029 | AB8: 0.119188
A9: MA0000030306 | B9: 3030 | C9: CDG TRESORERIE | D9: CDG CAPITAL GESTION | E9: SICAV | F9: MONÉTAIRE | G9: [0 0,5[ | H9: 50% MBI CT + 50% TMP | I9: QUOTIDIENNE | J9: FGP | K9: CAPITALISANT | L9: 0 | M9: 0 | N9: 0.02 | O9: CDG CAPITAL | P9: CDG CAPITAL GESTION | Q9: 5.2254534e+09 | R9: 2278.57 | S9: 0.01811 | T9: - | U9: 0.000624 | V9: 0.00242 | W9: 0.007423 | X9: 0.014294 | Y9: 0.026637 | Z9: 0.057375 | AA9: 0.094451 | AB9: 0.138135
A10: MA0000030363 | B10: 3036 | C10: BMCI EPARGNE CROISSANCE | D10: CIH CAPITAL MANAGEMENT | E10: SICAV | F10: DIVERSIFIÉ | G10: - | H10: 60% MASI + 40% MBI MT | I10: HEBDOMADAIRE | J10: FGP | K10: CAPITALISANT | L10: 0.0125 | M10: 0.005 | N10: 0.0195 | O10: BMCI | P10: CIH CAPITAL MANAGEMENT | Q10: 2.7352334e+08 | R10: 165.82 | S10: -0.013798 | T10: - | U10: 0.004848 | V10: 0.023391 | W10: 0.0183 | X10: -0.009557 | Y10: -0.044265 | Z10: 0.143192 | AA10: 0.271723 | AB10: 0.278883
A11: MA0000030371 | B11: 3037 | C11: CIMR TRESO PLUS | D11: SAHAM CAPITAL GESTION | E11: SICAV | F11: OCT | G11: ]0,5 1,1] | H11: MBI CT | I11: QUOTIDIENNE | J11: FNPP | K11: CAPITALISANT | L11: 0 | M11: 0 | N11: 0.02 | O11: SAHAM BANK | P11: SAHAM BANK | Q11: 1.3705129e+08 | R11: 403092.03 | S11: 0.015963 | T11: - | U11: 0.000608 | V11: 0.001914 | W11: 0.006369 | X11: 0.012233 | Y11: 0.021941 | Z11: 0.051635 | AA11: 0.089465 | AB11: 0.132169
A12: MA0000030397 | B12: 3039 | C12: CDG BARID | D12: CDG CAPITAL GESTION | E12: SICAV | F12: OMLT | G12: [3 7[ | H12: - | I12: HEBDOMADAIRE | J12: FNPP | K12: CAPITALISANT | L12: 0.005 | M12: 0 | N12: 0.02 | O12: CDG | P12: CDG CAPITAL GESTION | Q12: 3.4367662e+09 | R12: 3733.53 | S12: -0.005773 | T12: - | U12: 0.001792 | V12: 0.007578 | W12: 0.005456 | X12: -0.00475 | Y12: -0.016039 | Z12: 0.083697 | AA12: 0.184717 | AB12: 0.076848
A13: MA0000030405 | B13: 3040 | C13: SICAV MAROC CROISSANCE | D13: MAROGEST | E13: SICAV | F13: DIVERSIFIÉ | G13: - | H13: - | I13: HEBDOMADAIRE | J13: FGP | K13: CAPITALISANT | L13: 0.02 | M13: 0.005 | N13: 0.02 | O13: CIH BANK | P13: MAROGEST | Q13: 3.0700823e+08 | R13: 5231.91 | S13: -0.03534 | T13: - | U13: 0.004072 | V13: 0.032381 | W13: 0.02404 | X13: -0.034236 | Y13: -0.096243 | Z13: 0.153974 | AA13: 0.356521 | AB13: 0.347298
A14: MA0000030413 | B14: 3041 | C14: BMCI CASH | D14: CIH CAPITAL MANAGEMENT | E14: SICAV | F14: OCT | G14: [0,6 1,1[ | H14: MBI CT | I14: QUOTIDIENNE | J14: FGP | K14: CAPITALISANT | L14: 0 | M14: 0 | N14: 0.0067 | O14: BMCI | P14: CIH CAPITAL MANAGEMENT | Q14: 31219914 | R14: 196.45 | S14: 0.020944 | T14: - | U14: 0.000509 | V14: 0.004602 | W14: 0.010389 | X14: 0.018351 | Y14: 0.031829 | Z14: 0.063444 | AA14: 0.094002 | AB14: 0.115813
... A57: MA0000035453 | B57: 3545 | C57: SCR INTEGRALE | D57: CDG CAPITAL GESTION | E57: FCP | F57: ACTIONS | G57: - | H57: CFG 25 FLOTTANT | I57: HEBDOMADAIRE | J57: FNPP | K57: DISTRIBUANT | L57: 0.03 | M57: 0.015 | N57: 0.02 | O57: CDG CAPITAL | P57: CDG CAPITAL GESTION | Q57: 2.303213e+08 | R57: 6690.13 | S57: -0.038433 | T57: - | U57: 0.010406 | V57: 0.071733 | W57: 0.054994 | X57: -0.022108 | Y57: -0.131005 | Z57: 0.277403 | AA57: 0.497753 | AB57: 0.438198
A58: MA0000035461 | B58: 3546 | C58: SCR OBLIGATIONS | D58: CDG CAPITAL GESTION | E58: FCP | F58: OMLT | G58: ]1,1 9] | H58: MBI GLOBAL | I58: HEBDOMADAIRE | J58: FNPP | K58: CAPITALISANT | L58: 0 | M58: 0 | N58: - | O58: CDG CAPITAL | P58: CDG CAPITAL GESTION | Q58: 2.4209056e+09 | R58: 2731.36 | S58: -0.001334 | T58: - | U58: 0.001188 | V58: 0.004306 | W58: 0.00483 | X58: -0.001193 | Y58: -0.006446 | Z58: 0.084771 | AA58: 0.18333 | AB58: 0.080557
A59: MA0000035487 | B59: 3548 | C59: CDG ACTIONS | D59: CDG CAPITAL GESTION | E59: FCP | F59: ACTIONS | G59: - | H59: CFG 25 FLOTTANT | I59: HEBDOMADAIRE | J59: FNPP | K59: CAPITALISANT | L59: 0.03 | M59: 0.015 | N59: 0.02 | O59: CDG CAPITAL | P59: CDG CAPITAL GESTION | Q59: 1.792654e+09 | R59: 7774.13 | S59: -0.014334 | T59: - | U59: 0.015106 | V59: 0.081716 | W59: 0.065523 | X59: -0.001513 | Y59: -0.114996 | Z59: 0.241263 | AA59: 0.420996 | AB59: 0.373427
A60: MA0000035495 | B60: 3549 | C60: AL IKRAM | D60: CIH CAPITAL MANAGEMENT | E60: FCP | F60: DIVERSIFIÉ | G60: - | H60: 60% MASI + 40% MBI MT | I60: HEBDOMADAIRE | J60: FNPP | K60: CAPITALISANT | L60: 0.03 | M60: 0.015 | N60: 0.0075 | O60: BMCI | P60: CIH CAPITAL MANAGEMENT | Q60: 35007207 | R60: 36849.69 | S60: -0.000661 | T60: - | U60: 0.001643 | V60: 0.014847 | W60: 0.014993 | X60: 0.00318 | Y60: -0.026422 | Z60: 0.129366 | AA60: 0.235448 | AB60: 0.255718
A61: MA0000035503 | B61: 3550 | C61: CASACTIONS | D61: CIH CAPITAL MANAGEMENT | E61: FCP | F61: DIVERSIFIÉ | G61: - | H61: 80% MBI GLOBAL + 20% MASI | I61: HEBDOMADAIRE | J61: FNPP | K61: DISTRIBUANT | L61: 0.03 | M61: 0.015 | N61: 0.02 | O61: BMCI | P61: CIH CAPITAL MANAGEMENT | Q61: 2471148.6 | R61: 176510.61 | S61: 0.000125 | T61: - | U61: 0.000821 | V61: 0.002192 | W61: 0.003305 | X61: 0.001332 | Y61: -0.001839 | Z61: 0.011621 | AA61: 0.032218 | AB61: 0.031679
A62: MA0000035511 | B62: 3551 | C62: AVENIR ACTIONS | D62: CIH CAPITAL MANAGEMENT | E62: FCP | F62: DIVERSIFIÉ | G62: - | H62: 80% MBI GLOBAL + 20% MASI | I62: HEBDOMADAIRE | J62: FNPP | K62: DISTRIBUANT | L62: 0.03 | M62: 0.015 | N62: 0.02 | O62: BMCI | P62: CIH CAPITAL MANAGEMENT | Q62: 226365390 | R62: 250404.19 | S62: 0.002198 | T62: - | U62: 0.005349 | V62: 0.030053 | W62: 0.02379 | X62: 0.00182 | Y62: -0.044081 | Z62: 0.139823 | AA62: 0.25105 | AB62: 0.24884
A63: MA0000035529 | B63: 3552 | C63: AXA HORIZON | D63: CIH CAPITAL MANAGEMENT | E63: FCP | F63: DIVERSIFIÉ | G63: - | H63: CFG 25 FLOTTANT | I63: HEBDOMADAIRE | J63: FNPP | K63: MIXTE | L63: 0.03 | M63: 0.015 | N63: 0 | O63: BMCI | P63: CIH CAPITAL MANAGEMENT | Q63: 8.2454502e+08 | R63: 181497.91 | S63: 0.010424 | T63: - | U63: 0.005996 | V63: 0.026809 | W63: 0.022661 | X63: 0.007734 | Y63: -0.023711 | Z63: 0.196411 | AA63: 0.335349 | AB63: 0.295967
A64: MA0000035537 | B64: 3553 | C64: CIMR THARWA | D64: CIH CAPITAL MANAGEMENT | E64: FCP | F64: ACTIONS | G64: - | H64: MASI RN | I64: HEBDOMADAIRE | J64: FNPP | K64: CAPITALISANT | L64: 0 | M64: 0 | N64: 0.02 | O64: BMCI | P64: CIH CAPITAL MANAGEMENT | Q64: 1.1656895e+09 | R64: 524612.73 | S64: 0.03992 | T64: - | U64: 0.015904 | V64: 0.082095 | W64: 0.063812 | X64: 0.040307 | Y64: -0.052075 | Z64: 0.403137 | AA64: 0.659227 | AB64: 0.675629
A65: MA0000035545 | B65: 3554 | C65: BMCI INVEST | D65: CIH CAPITAL MANAGEMENT | E65: FCP | F65: DIVERSIFIÉ | G65: - | H65: 60% MASI + 40% MBI MT | I65: HEBDOMADAIRE | J65: FNPP | K65: CAPITALISANT | L65: 0.03 | M65: 0.015 | N65: 0.006 | O65: BMCI | P65: CIH CAPITAL MANAGEMENT | Q65: 839472.75 | R65: 239.85 | S65: 0.004902 | T65: - | U65: -0.00025 | V65: 0.011129 | W65: -0.004607 | X65: -0.000458 | Y65: -0.011906 | Z65: 0.044324 | AA65: 0.067756 | AB65: 0.059221
A66: MA0000035552 | B66: 3555 | C66: AXA AVENIR | D66: CDG CAPITAL GESTION | E66: FCP | F66: DIVERSIFIÉ | G66: - | H66: 80% MBI GLOBAL + 25% MASI RN | I66: HEBDOMADAIRE | J66: FNPP | K66: MIXTE | L66: 0.03 | M66: 0.015 | N66: 0.02 | O66: CDG CAPITAL | P66: CDG CAPITAL GESTION | Q66: 7.8287141e+08 | R66: 3660.22 | S66: -0.015877 | T66: - | U66: 0.005119 | V66: 0.025961 | W66: 0.021215 | X66: -0.011906 | Y66: -0.059141 | Z66: 0.146368 | AA66: 0.251108 | AB66: 0.201625
A67: MA0000035594 | B67: 3559 | C67: HORIZON BALANCED FUND | D67: SAHAM CAPITAL GESTION | E67: FCP | F67: DIVERSIFIÉ | G67: - | H67: 50% MBI GLOBAL + 50% MASI | I67: QUOTIDIENNE | J67: FGP | K67: DISTRIBUANT | L67: 0.02 | M67: 0.015 | N67: 0.02 | O67: SAHAM BANK | P67: SAHAM BANK | Q67: 1293595.6 | R67: 107799.63 | S67: -0.00143 | T67: - | U67: 0.007262 | V67: 0.03519 | W67: -0.005421 | X67: -0.006674 | Y67: -0.049498 | Z67: 0.189829 | AA67: 0.362213 | AB67: 0.381902
A68: MA0000035651 | B68: 3565 | C68: ATLAS PREMIUM | D68: ATLAS CAPITAL MANAGEMENT | E68: FCP | F68: ACTIONS | G68: - | H68: MASI | I68: HEBDOMADAIRE | J68: FGP | K68: CAPITALISANT | L68: 0.03 | M68: 0.015 | N68: 0.015 | O68: CIH BANK | P68: ATLAS CAPITAL MANAGEMENT | Q68: 1052815.6 | R68: 767.91 | S68: 0.05124 | T68: - | U68: 0.014452 | V68: 0.077738 | W68: 0.063749 | X68: 0.044989 | Y68: -0.046868 | Z68: 0.44325 | AA68: 0.700044 | AB68: 0.659628
A69: MA0000035677 | B69: 3567 | C69: CDG HORIZONS | D69: CDG CAPITAL GESTION | E69: FCP | F69: OMLT | G69: ]1,1 5,1] | H69: 50% MBI MLT + 50% MBI MT | I69: QUOTIDIENNE | J69: FGP | K69: CAPITALISANT | L69: 0.03 | M69: 0.015 | N69: 0.02 | O69: CDG CAPITAL | P69: CDG CAPITAL GESTION | Q69: 2.3065998e+08 | R69: 2257.05 | S69: 0.00705 | T69: - | U69: 0.000656 | V69: 0.003325 | W69: 0.005605 | X69: 0.005511 | Y69: 0.013002 | Z69: 0.086306 | AA69: 0.143349 | AB69: 0.130934
A70: MA0000035685 | B70: 3568 | C70: AVENIR OBLIGATION | D70: CFG GESTION | E70: FCP | F70: OMLT | G70: [4 8[ | H70: CFG BONDS MT | I70: HEBDOMADAIRE | J70: FNPP | K70: MIXTE | L70: 0 | M70: 0 | N70: 0.01 | O70: ATTIJARIWAFA BANK | P70: CFG GESTION | Q70: 1.4021896e+09 | R70: 26110.57 | S70: -0.002706 | T70: - | U70: 0.000853 | V70: 0.002806 | W70: 0.001529 | X70: -0.00326 | Y70: -0.011532 | Z70: 0.07997 | AA70: 0.180455 | AB70: 0.087448
... A118: MA0000036329 | B118: 3632 | C118: FCP CAPITAL TERME | D118: BMCE CAPITAL GESTION | E118: FCP | F118: DIVERSIFIÉ | G118: - | H118: 80% MBI GLOBAL + 20% MASI | I118: QUOTIDIENNE | J118: FGP | K118: CAPITALISANT | L118: 0.02 | M118: 0.02 | N118: 0.02 | O118: BANK OF AFRICA | P118: BMCE CAPITAL GESTION | Q118: 81346694 | R118: 249.05 | S118: 0.025826 | T118: - | U118: 0.003748 | V118: 0.019652 | W118: 0.033402 | X118: 0.024307 | Y118: -0.003202 | Z118: 0.177096 | AA118: 0.301202 | AB118: 0.257447
A119: MA0000036345 | B119: 3634 | C119: CFG INSTIBONDS | D119: CFG GESTION | E119: FCP | F119: OMLT | G119: ]1,5 5,5] | H119: MBI GLOBAL | I119: QUOTIDIENNE | J119: FGP | K119: CAPITALISANT | L119: 0.03 | M119: 0.015 | N119: 0.02 | O119: CFG BANK | P119: CFG GESTION; CFG BANK | Q119: 5.5249415e+08 | R119: 34.15 | S119: 0.00176 | T119: - | U119: 0.000879 | V119: 0.004116 | W119: 0.003821 | X119: -0.001462 | Y119: -0.780386 | Z119: -0.767133 | AA119: -0.754969 | AB119: -
A120: MA0000036352 | B120: 3635 | C120: FCP CAM TRESO PLUS | D120: MAROGEST | E120: FCP | F120: OCT | G120: ]0,5 1,1] | H120: 85% MBI CT + 15 % MBI MT | I120: QUOTIDIENNE | J120: FGP | K120: CAPITALISANT | L120: 0.03 | M120: 0.015 | N120: 0.02 | O120: CIH BANK | P120: CIH | Q120: 8.8535144e+08 | R120: 174.74 | S120: 0.018595 | T120: - | U120: 0.000745 | V120: 0.002237 | W120: 0.007379 | X120: 0.01422 | Y120: 0.026313 | Z120: 0.062701 | AA120: 0.10553 | AB120: 0.151803
A121: MA0000036378 | B121: 3637 | C121: AVENIR CROISSANCE | D121: CFG GESTION | E121: FCP | F121: ACTIONS | G121: - | H121: CFG 25 FLOTTANT | I121: HEBDOMADAIRE | J121: FNPP | K121: MIXTE | L121: 0.03 | M121: 0.015 | N121: 0.02 | O121: ATTIJARIWAFA BANK | P121: CFG GESTION | Q121: 1307500.1 | R121: 36319.45 | S121: -0.031662 | T121: - | U121: 0.004315 | V121: 0.039068 | W121: 0.030488 | X121: -0.031372 | Y121: -0.117025 | Z121: 0.217066 | AA121: 0.457583 | AB121: 0.449455
A122: MA0000036394 | B122: 3639 | C122: FCP CAPITAL TAALIM | D122: BMCE CAPITAL GESTION | E122: FCP | F122: OMLT | G122: [4 8[ | H122: 95% MBI MLT + 5% MASI | I122: HEBDOMADAIRE | J122: FNPP | K122: CAPITALISANT | L122: 0.03 | M122: 0.015 | N122: 0.02 | O122: BANK OF AFRICA | P122: BMCE CAPITAL GESTION | Q122: 3.5534625e+09 | R122: 2373.64 | S122: -0.000644 | T122: - | U122: 0.002081 | V122: 0.008587 | W122: 0.007474 | X122: -0.001073 | Y122: -0.014429 | Z122: 0.109748 | AA122: 0.225623 | AB122: 0.168538
A123: MA0000036402 | B123: 3640 | C123: UPLINE EQUILIBRE | D123: UPLINE CAPITAL MANAGEMENT | E123: FCP | F123: DIVERSIFIÉ | G123: - | H123: 75% MBI GLOBAL + 25% MASI 20 | I123: QUOTIDIENNE | J123: FNPP | K123: MIXTE | L123: 0 | M123: 0 | N123: 0.02 | O123: BCP | P123: UPLINE CAPITAL MANAGEMENT | Q123: 5.7343279e+08 | R123: 125.57 | S123: 0.013412 | T123: - | U123: 0.006654 | V123: 0.036227 | W123: 0.029853 | X123: 0.013968 | Y123: -0.039624 | Z123: -0.070169 | AA123: -0.042015 | AB123: -0.078932
A124: MA0000036436 | B124: 3643 | C124: EMERGENCE CAPITAL | D124: VALORIS MANAGEMENT | E124: FCP | F124: OMLT | G124: [1,1 5,1[ | H124: MBI GLOBAL | I124: HEBDOMADAIRE | J124: FGP | K124: CAPITALISANT | L124: 0.03 | M124: 0.015 | N124: 0.005 | O124: BANK OF AFRICA | P124: VALORIS MANAGEMENT | Q124: 2.7334802e+08 | R124: 1799.77 | S124: 0.005351 | T124: - | U124: 0.000873 | V124: 0.002568 | W124: 0.004807 | X124: 0.004129 | Y124: 0.005615 | Z124: 0.065571 | AA124: 0.129105 | AB124: 0.110997
A125: MA0000036444 | B125: 3644 | C125: AL IJTIMAI PATRIMOINE | D125: VALORIS MANAGEMENT | E125: FCP | F125: OMLT | G125: [1,1 7,1[ | H125: MBI GLOBAL | I125: HEBDOMADAIRE | J125: FNPP | K125: CAPITALISANT | L125: 0.03 | M125: 0.015 | N125: 0.008 | O125: CDG | P125: VALORIS MANAGEMENT | Q125: 5.0380953e+09 | R125: 213795.68 | S125: 0.002191 | T125: - | U125: 0.001744 | V125: 0.006867 | W125: 0.007323 | X125: 0.002058 | Y125: -0.007078 | Z125: 0.101811 | AA125: 0.214506 | AB125: 0.136983
A126: MA0000036485 | B126: 3648 | C126: CAT ACTIONS | D126: CIH CAPITAL MANAGEMENT | E126: FCP | F126: ACTIONS | G126: - | H126: MASI RN | I126: HEBDOMADAIRE | J126: FNPP | K126: DISTRIBUANT | L126: 0 | M126: 0 | N126: 0.02 | O126: BMCI | P126: CIH CAPITAL MANAGEMENT | Q126: 2.9373739e+08 | R126: 513526.9 | S126: 0.025974 | T126: - | U126: 0.015267 | V126: 0.079545 | W126: 0.064483 | X126: 0.024318 | Y126: -0.06851 | Z126: 0.369246 | AA126: 0.578165 | AB126: 0.576016
A127: MA0000036493 | B127: 3649 | C127: FCP CAPITAL MAGHREB | D127: BMCE CAPITAL GESTION | E127: FCP | F127: ACTIONS | G127: - | H127: MASI | I127: QUOTIDIENNE | J127: FGP | K127: CAPITALISANT | L127: 0.02 | M127: 0.02 | N127: 0.02 | O127: BANK OF AFRICA | P127: BMCE CAPITAL GESTION | Q127: 1.5288164e+09 | R127: 1825.43 | S127: 0.026578 | T127: - | U127: 0.014584 | V127: 0.079134 | W127: 0.061562 | X127: 0.028504 | Y127: -0.084323 | Z127: 0.412882 | AA127: 0.728021 | AB127: 0.661823
A128: MA0000036501 | B128: 3650 | C128: FCP CAPITAL MULTI-GESTION | D128: BMCE CAPITAL GESTION | E128: FCP | F128: DIVERSIFIÉ | G128: - | H128: 80% MBI GLOBAL + 20% MASI | I128: QUOTIDIENNE | J128: FGP | K128: CAPITALISANT | L128: 0.02 | M128: 0.02 | N128: 0.02 | O128: BANK OF AFRICA | P128: BMCE CAPITAL GESTION | Q128: 1.758446e+09 | R128: 547.39 | S128: -0.010735 | T128: - | U128: 0.004607 | V128: 0.02617 | W128: 0.017605 | X128: -0.007632 | Y128: -0.056501 | Z128: 0.148941 | AA128: 0.270135 | AB128: 0.17774
A129: MA0000036519 | B129: 3651 | C129: FCP AL IJTIMAI SECURITE | D129: BMCE CAPITAL GESTION | E129: FCP | F129: OMLT | G129: [1,1 7[ | H129: MBI GLOBAL | I129: HEBDOMADAIRE | J129: FNPP | K129: CAPITALISANT | L129: 0.03 | M129: 0.015 | N129: 0.02 | O129: BANK OF AFRICA | P129: BMCE CAPITAL GESTION | Q129: 3.0215812e+09 | R129: 225339.78 | S129: -0.002127 | T129: - | U129: 0.001795 | V129: 0.007851 | W129: 0.006543 | X129: -0.002662 | Y129: -0.015547 | Z129: 0.098135 | AA129: 0.209569 | AB129: 0.151806
...

Sheet 31_12_25
A1: Tableau des performances quotidiennes au 31-12-2025
A2: CODE ISIN | B2: Code Maroclear | C2: OPCVM | D2: Société de Gestion | E2: Nature juridique | F2: Classification | G2: Sensibilité | H2: Indice Bentchmark | I2: Périodicité VL | J2: Souscripteurs | K2: Affectation des résultats | L2: Commission de souscription | M2: Commission de rachat | N2: Frais de gestion | O2: Dépositaire | P2: Réseau placeur | Q2: AN | R2: VL | S2: YTD | T2: 1 jour | U2: 1 semaine | V2: 1 mois | W2: 3 mois | X2: 6 mois | Y2: 1 an | Z2: 2 ans | AA2: 3 ans | AB2: 5 ans
A3: MA0000030132 | B3: 3013 | C3: BMCI TRESORERIE | D3: CIH CAPITAL MANAGEMENT | E3: SICAV | F3: MONÉTAIRE | G3: [0 0,5[ | H3: TMJ(jj) | I3: QUOTIDIENNE | J3: FGP | K3: CAPITALISANT | L3: 0.0125 | M3: 0.005 | N3: 0.0195 | O3: BMCI | P3: CIH CAPITAL MANAGEMENT | Q3: 1.5919419e+08 | R3: 122268.97 | S3: 0.016149 | T3: 0.00011 | U3: 0.000386 | V3: 0.001304 | W3: 0.003661 | X3: 0.00739 | Y3: 0.016149 | Z3: 0.038772 | AA3: 0.061869 | AB3: 0.078071
A4: MA0000030280 | B4: 3028 | C4: CDG TAWFIR | D4: CDG CAPITAL GESTION | E4: SICAV | F4: OMLT | G4: [3 7[ | H4: MBI GLOBAL | I4: QUOTIDIENNE | J4: FGP | K4: CAPITALISANT | L4: 0.005 | M4: 0 | N4: 0.02 | O4: CDG CAPITAL | P4: CDG CAPITAL GESTION | Q4: 1.3015908e+09 | R4: 3477.03 | S4: 0.053492 | T4: -0.000354 | U4: -0.002828 | V4: 0.005099 | W4: -0.004153 | X4: 0.008615 | Y4: 0.053492 | Z4: 0.137489 | AA4: 0.147652 | AB4: 0.12209
A5: MA0000030298 | B5: 3029 | C5: SICAV OBLIGATIONS PÉRENNITÉ | D5: CDG CAPITAL GESTION | E5: SICAV | F5: OMLT | G5: [1,1 16[ | H5: MBI MT | I5: QUOTIDIENNE | J5: FNPP | K5: CAPITALISANT | L5: 0.03 | M5: 0.015 | N5: 0.02 | O5: CDG CAPITAL | P5: CDG CAPITAL GESTION | Q5: 6.0010649e+09 | R5: 3313.59 | S5: 0.037095 | T5: -0.00092 | U5: -0.000667 | V5: 0.00441 | W5: -0.000181 | X5: 0.007614 | Y5: 0.037095 | Z5: 0.092905 | AA5: 0.121316 | AB5: 0.139725
A6: MA0000030306 | B6: 3030 | C6: CDG TRESORERIE | D6: CDG CAPITAL GESTION | E6: SICAV | F6: MONÉTAIRE | G6: [0 0,5[ | H6: 50% MBI CT + 50% TMP | I6: QUOTIDIENNE | J6: FGP | K6: CAPITALISANT | L6: 0 | M6: 0 | N6: 0.02 | O6: CDG CAPITAL | P6: CDG CAPITAL GESTION | Q6: 5.1469756e+09 | R6: 2239.01 | S6: 0.027724 | T6: 0.000273 | U6: 0.000724 | V6: 0.002287 | W6: 0.006351 | X6: 0.012788 | Y6: 0.027724 | Z6: 0.062825 | AA6: 0.099316 | AB6: 0.127953
A7: MA0000030371 | B7: 3037 | C7: CIMR TRESO PLUS | D7: SAHAM CAPITAL GESTION | E7: SICAV | F7: OCT | G7: ]0,5 1,1] | H7: MBI CT | I7: QUOTIDIENNE | J7: FNPP | K7: CAPITALISANT | L7: 0 | M7: 0 | N7: 0.02 | O7: SAHAM BANK | P7: SAHAM BANK | Q7: 2.0872146e+08 | R7: 396808.85 | S7: 0.024736 | T7: -0.000112 | U7: 0.000297 | V7: 0.002071 | W7: 0.004259 | X7: 0.009488 | Y7: 0.024736 | Z7: 0.05965 | AA7: 0.09669 | AB7: 0.126277
A8: MA0000030413 | B8: 3041 | C8: BMCI CASH | D8: CIH CAPITAL MANAGEMENT | E8: SICAV | F8: OCT | G8: [0,6 1,1[ | H8: MBI CT | I8: QUOTIDIENNE | J8: FGP | K8: CAPITALISANT | L8: 0 | M8: 0 | N8: 0.0067 | O8: BMCI | P8: CIH CAPITAL MANAGEMENT | Q8: 35914363 | R8: 192.46 | S8: 0.0303 | T8: 0.000104 | U8: 0.000364 | V8: 0.002031 | W8: 0.007117 | X8: 0.016156 | Y8: 0.0303 | Z8: 0.061614 | AA8: 0.087406 | AB8: 0.100337
A9: MA0000030470 | B9: 3047 | C9: CFG CROISSANCE | D9: CFG GESTION | E9: SICAV | F9: DIVERSIFIÉ | G9: - | H9: 50% CFG 25 FLOTTANT + 50% CFG BONDS CT | I9: QUOTIDIENNE | J9: FGP | K9: CAPITALISANT | L9: 0.002 | M9: 0.002 | N9: 0.015 | O9: CFG BANK | P9: CFG GESTION; CFG BANK | Q9: 1.7378724e+09 | R9: 9863.68 | S9: 0.154377 | T9: 0.00428 | U9: -0.01085 | V9: -0.000502 | W9: -0.01863 | X9: -0.006293 | Y9: 0.154377 | Z9: 0.341818 | AA9: 0.396623 | AB9: 0.377334
A10: MA0000030488 | B10: 3048 | C10: IRAD | D10: BMCE CAPITAL GESTION | E10: SICAV | F10: MONÉTAIRE | G10: <0,5 | H10: Taux Repo au jour le jour | I10: QUOTIDIENNE | J10: FGP | K10: CAPITALISANT | L10: 0 | M10: 0 | N10: 0.015 | O10: BANK OF AFRICA | P10: BMCE CAPITAL GESTION | Q10: 3.2013232e+09 | R10: 2747.19 | S10: 0.028413 | T10: 0.000557 | U10: 0.001046 | V10: 0.002749 | W10: 0.006573 | X10: 0.013248 | Y10: 0.028413 | Z10: 0.064006 | AA10: 0.100708 | AB10: 0.137101
A11: MA0000030512 | B11: 3051 | C11: HORIZON EXPANSION | D11: UPLINE CAPITAL MANAGEMENT | E11: SICAV | F11: DIVERSIFIÉ | G11: - | H11: 40% TMP + 60% MASI | I11: QUOTIDIENNE | J11: FGP | K11: CAPITALISANT | L11: 0.01 | M11: 0.005 | N11: 0.02 | O11: BCP | P11: UPLINE CAPITAL MANAGEMENT | Q11: 4719516.2 | R11: 42904.69 | S11: 0.158641 | T11: 0.004749 | U11: -0.004217 | V11: 0.007959 | W11: -7.6e-05 | X11: 0.011769 | Y11: 0.158641 | Z11: 0.307866 | AA11: 0.405262 | AB11: 0.393502
A12: MA0000030520 | B12: 3052 | C12: ATTIJARI DIVERSIFIE | D12: WAFA GESTION | E12: SICAV | F12: DIVERSIFIÉ | G12: - | H12: 30% MASI + 70% MBI MT | I12: QUOTIDIENNE | J12: FGP | K12: CAPITALISANT | L12: 0.03 | M12: 0.015 | N12: 0.02 | O12: ATTIJARIWAFA BANK | P12: WAFA GESTION | Q12: 3.3487515e+09 | R12: 724.38 | S12: 0.135214 | T12: 0.004813 | U12: -0.006842 | V12: 0.008563 | W12: -0.003919 | X12: 0.008858 | Y12: 0.135214 | Z12: - | AA12: 0.350876 | AB12: -
